<?xml version="1.0"?>
<robot xmlns:xacro="http://www.ros.org/wiki/xacro">
 
  <xacro:macro name="iiwa7" params="parent robot_name *origin">
  <xacro:property name="safety_controller_k_pos" value="100" />
  <xacro:property name="safety_controller_k_vel" value="2" /> 
  <xacro:property name="joint_damping" value="0.5" />
  <xacro:property name="max_effort" value="300"/>
  <xacro:property name="max_velocity" value="10"/>
  
	<xacro:macro name="transmission_block" params="joint_name">
			<transmission name="${joint_name}_tran1">
			  <type>transmission_interface/SimpleTransmission</type>
			  <joint name="${joint_name}">
			    <hardwareInterface>hardware_interface/PositionJointInterface</hardwareInterface>
			  </joint>
			  <actuator name="${joint_name}_motor">
			    <hardwareInterface>hardware_interface/PositionJointInterface</hardwareInterface>
			    <mechanicalReduction>1</mechanicalReduction>
			  </actuator>
			</transmission>
		 </xacro:macro>
		 		 
  
    
    <!--joint between {parent} and link_0-->
    <joint name="${parent}_${robot_name}_joint" type="fixed">
      <xacro:insert_block name="origin"/>
      <parent link="${parent}"/>
      <child link="${robot_name}_link_0"/>
    </joint>
    
    <link name="${robot_name}_link_0">
      <inertial>
        <origin xyz="-0.3 0 0.21" rpy="0 0 0"/>
        <mass value="5"/>
        <inertia ixx="0.05"  ixy="0"  ixz="0" iyy="0.06" iyz="0" izz="0.03" />
      </inertial>
      
      <visual>
        <origin xyz="0 0 0" rpy="0 0 0"/>
        <geometry>
          <mesh filename="package://mirzaagha_rl/meshes/iiwa7/visual/link_0.stl" scale="3 3 3"/>
        </geometry>
        <material name="Grey"/>
      </visual>
      
      <collision>
        <origin xyz="0 0 0" rpy="0 0 0"/>
        <geometry>
          <mesh filename="package://mirzaagha_rl/meshes/iiwa7/collision/link_0.stl" scale="3 3 3"/>
        </geometry>
        <material name="Grey"/>
      </collision>
      
      <self_collision_checking>
        <origin xyz="0 0 0" rpy="0 0 0"/>
        <geometry>
          <capsule radius="0.45" length="0.75"/>
        </geometry>
      </self_collision_checking>
      
    </link>
    
    <!-- joint between link_0 and link_1 -->
    <joint name="${robot_name}_joint_1" type="revolute">
      <parent link="${robot_name}_link_0"/>
      <child link="${robot_name}_link_1"/>
      <origin xyz="0 0 0.45" rpy="0 0 0"/>
      <axis xyz="0 0 1"/>
      <limit lower="${0 * PI / 180}" upper="${360 * PI / 180}"
             effort="${max_effort}" velocity="${max_velocity}" />
    </joint>
    
    <link name="${robot_name}_link_1">
      <inertial>
        <origin xyz="0 -0.09 0.36" rpy="0 0 0"/>
        <mass value="3.4525"/>
        <inertia ixx="0.02183"  ixy="0"  ixz="0" iyy="0.007703" iyz="-0.003887" izz="0.02083" />
      </inertial>
      <visual>
        <origin xyz="0 0 0.0225" rpy="0 0 0"/>
        <geometry>
          <mesh filename="package://mirzaagha_rl/meshes/iiwa7/visual/link_1.stl" scale="3 3 3"/>
        </geometry>
        <material name="Orange"/>
      </visual>
      <collision>
        <origin xyz="0 0 0.0225" rpy="0 0 0"/>
        <geometry>
          <mesh filename="package://mirzaagha_rl/meshes/iiwa7/collision/link_1.stl" scale="3 3 3"/>
        </geometry>
        <material name="Orange"/>
      </collision>
    </link>
    
    <joint name="${robot_name}_joint_2" type="revolute">
      <parent link="${robot_name}_link_1"/>
      <child link="${robot_name}_link_2"/>
      <origin xyz="0 0 0.57" rpy="${PI / 2}   0 ${PI}"/>
      <axis xyz="0 0 1"/>
      <limit lower="${-120 * PI / 180}" upper="${120 * PI / 180}"
             effort="${max_effort}" velocity="${max_velocity}" />
      <safety_controller soft_lower_limit="${-118 * PI / 180}"
                         soft_upper_limit="${118 * PI / 180}"
                         k_position="${safety_controller_k_pos}"
                         k_velocity="${safety_controller_k_vel}"/> 
      <dynamics damping="${joint_damping}"/>
    </joint>
    
    <link name="${robot_name}_link_2">
      <inertial>
        <origin xyz="0.0009 0.177 0.126" rpy="0 0 0"/>
        <mass value="3.4821"/>
        <inertia ixx="0.02076"  ixy="0"  ixz="-0.003626" iyy="0.02179" iyz="0" izz="0.00779" />
      </inertial>
      <visual>
        <origin xyz="0 0 0" rpy="0 0 0"/>
        <geometry>
          <mesh filename="package://mirzaagha_rl/meshes/iiwa7/visual/link_2.stl" scale="3 3 3"/>
        </geometry>
        <material name="Orange"/>
      </visual>
      
      <collision>
        <origin xyz="0 0 0" rpy="0 0 0"/>
        <geometry>
          <mesh filename="package://mirzaagha_rl/meshes/iiwa7/collision/link_2.stl" scale="3 3 3"/>
        </geometry>
        <material name="Orange"/>
      </collision>
    </link>
    
    <joint name="${robot_name}_joint_3" type="revolute">
      <parent link="${robot_name}_link_2"/>
      <child link="${robot_name}_link_3"/>
      <origin xyz="0 0.63 0" rpy="${PI / 2} 0 ${PI}"/>
      <axis xyz="0 0 1"/>
			
      <limit lower="${-170 * PI / 180}" upper="${170 * PI / 180}"
             effort="${max_effort}" velocity="${max_velocity}" />
    </joint>
    
    <link name="${robot_name}_link_3">
      <inertial>
        <origin xyz="0 0.102 0.39" rpy="0 0 0"/>
        <mass value="4.05623"/>
        <inertia ixx="0.03204"  ixy="0"  ixz="0" iyy="0.00972" iyz="0.006227" izz="0.03042" />
      </inertial>
      
      <visual>
        <origin xyz="0 0 -0.078" rpy="0 0 0"/>
        <geometry>
          <mesh filename="package://mirzaagha_rl/meshes/iiwa7/visual/link_3.stl" scale="3 3 3"/>
        </geometry>
        <material name="Orange"/>
      </visual>
      
      <collision>
        <origin xyz="0 0 -0.078" rpy="0 0 0"/>
        <geometry>
          <mesh filename="package://mirzaagha_rl/meshes/iiwa7/collision/link_3.stl" scale="3 3 3"/>
        </geometry>
        <material name="Orange"/>
      </collision>
      
    </link>
    
    <joint name="${robot_name}_joint_4" type="revolute">
      <parent link="${robot_name}_link_3"/>
      <child link="${robot_name}_link_4"/>
      <origin xyz="0 0 0.57" rpy="${PI / 2} 0 0"/>
      <axis xyz="0 0 1"/>
      <limit lower="${-120 * PI / 180}" upper="${120 * PI / 180}"
             effort="${max_effort}" velocity="${max_velocity}" />
    </joint>
    
    <link name="${robot_name}_link_4">
      <inertial>
        <origin xyz="0 0.201 0.102" rpy="0 0 0"/>
        <mass value="3.4822"/>
        <inertia ixx="0.02178"  ixy="0"  ixz="0" iyy="0.02075" iyz="-0.003625" izz="0.007785" />
      </inertial>
      
      <visual>
        <origin xyz="0 0 0" rpy="0 0 0"/>
        <geometry>
          <mesh filename="package://mirzaagha_rl/meshes/iiwa7/visual/link_4.stl" scale="3 3 3"/>
        </geometry>
        <material name="Orange"/>
      </visual>
      
      <collision>
        <origin xyz="0 0 0" rpy="0 0 0"/>
        <geometry>
          <mesh filename="package://mirzaagha_rl/meshes/iiwa7/collision/link_4.stl" scale="3 3 3"/>
        </geometry>
        <material name="Orange"/>
      </collision>
    </link>
    
    <joint name="${robot_name}_joint_5" type="revolute">
      <parent link="${robot_name}_link_4"/>
      <child link="${robot_name}_link_5"/>
      <origin xyz="0 0.63 0" rpy="${-PI / 2} ${PI} 0"/>
      <axis xyz="0 0 1"/>
      <limit lower="${-170 * PI / 180}" upper="${170 * PI / 180}"
             effort="${max_effort}" velocity="${max_velocity}" />
    </joint>
    
    <link name="${robot_name}_link_5">
      <inertial>
        <origin xyz="0.0003 0.063 0.228" rpy="0 0 0"/>
        <mass value="2.1633"/>
        <inertia ixx="0.01287"  ixy="0"  ixz="0" iyy="0.005708" iyz="-0.003946" izz="0.01112" />
      </inertial>
      
      <visual>
        <origin xyz="0 0 -0.078" rpy="0 0 0"/>
        <geometry>
          <mesh filename="package://mirzaagha_rl/meshes/iiwa7/visual/link_5.stl" scale="3 3 3"/>
        </geometry>
        <material name="Orange"/>
      </visual>
      
      <collision>
        <origin xyz="0 0 -0.078" rpy="0 0 0"/>
        <geometry>
          <mesh filename="package://mirzaagha_rl/meshes/iiwa7/collision/link_5.stl" scale="3 3 3"/>
        </geometry>
        <material name="Orange"/>
      </collision>
    </link>
    
    <joint name="${robot_name}_joint_6" type="revolute">
      <parent link="${robot_name}_link_5"/>
      <child link="${robot_name}_link_6"/>
      <origin xyz="0 0.1821 0.57" rpy="${PI / 2} 0 0"/>
      <axis xyz="0 0 1"/>
      <limit lower="${-120 * PI / 180}" upper="${120 * PI / 180}"
             effort="${max_effort}" velocity="${max_velocity}" />
    </joint>
    
    <link name="${robot_name}_link_6">
      <inertial>
        <origin xyz="0 0.0018 0.0012" rpy="0 0 0"/>
        <mass value="2.3466"/>
        <inertia ixx="0.006509"  ixy="0"  ixz="0" iyy="0.006259" iyz="0.00031891" izz="0.004527" />
      </inertial>
      
      <visual>
        <origin xyz="0 0 0" rpy="0 0 0"/>
        <geometry>
          <mesh filename="package://mirzaagha_rl/meshes/iiwa7/visual/link_6.stl" scale="3 3 3"/>
        </geometry>
        <material name="Orange"/>
      </visual>
      
      <collision>
        <origin xyz="0 0 0" rpy="0 0 0"/>
        <geometry>
          <mesh filename="package://mirzaagha_rl/meshes/iiwa7/collision/link_6.stl" scale="3 3 3"/>
        </geometry>
        <material name="Orange"/>
      </collision>
    </link>
    
    <joint name="${robot_name}_joint_7" type="revolute">
      <parent link="${robot_name}_link_6"/>
      <child link="${robot_name}_link_7"/>
      <origin xyz="0 0.243 0.1821" rpy="${- PI / 2} ${PI} 0"/>
      <axis xyz="0 0 1"/>
      <limit lower="${-175 * PI / 180}" upper="${175 * PI / 180}"
             effort="${max_effort}" velocity="${max_velocity}" />
    </joint>
    
    <link name="${robot_name}_link_7">
      <inertial>
        <origin xyz="0 0 0.06" rpy="0 0 0"/>
        <mass value="3.129"/>
        <inertia ixx="0.01464"  ixy="0.0005912"  ixz="0" iyy="0.01465" iyz="0" izz="0.002872" />
      </inertial>
      
      <visual>
        <origin xyz="0 0 -0.0015" rpy="0 0 0"/>
        <geometry>
          <mesh filename="package://mirzaagha_rl/meshes/iiwa7/visual/link_7.stl" scale="3 3 3"/>
        </geometry>
        <material name="Grey"/>
      </visual>
      
      <collision>
        <origin xyz="0 0 -0.0015" rpy="0 0 0"/>
        <geometry>
          <mesh filename="package://mirzaagha_rl/meshes/iiwa7/collision/link_7.stl" scale="3 3 3"/>
        </geometry>
        <material name="Grey"/>
      </collision>
    </link>
    
    <joint name="${robot_name}_joint_ee" type="fixed">
      <parent link="${robot_name}_link_7"/>
      <child link="${robot_name}_link_ee"/>
      <origin xyz="0 0 0.135" rpy="0 ${- PI / 2} 0"/>
    </joint>
    
    <link name="${robot_name}_link_ee">
    </link>
    
        <joint name="${robot_name}_optical_joint" type="fixed">
    	<parent link="${robot_name}_link_7"/>
    	<child link="${robot_name}_optical_link"/>
    	<origin xyz="0 0 0.135" rpy="0 0 ${-PI/2}"/>
    </joint>
    
    <link name="${robot_name}_optical_link"/>
    
		<xacro:transmission_block joint_name="${robot_name}_joint_1"/>
		<xacro:transmission_block joint_name="${robot_name}_joint_2"/>
		<xacro:transmission_block joint_name="${robot_name}_joint_3"/>
		<xacro:transmission_block joint_name="${robot_name}_joint_4"/>
		<xacro:transmission_block joint_name="${robot_name}_joint_5"/>
		<xacro:transmission_block joint_name="${robot_name}_joint_6"/>
		<xacro:transmission_block joint_name="${robot_name}_joint_7"/>
		
		<gazebo>
			<plugin name="gazebo_ros_control" filename="libgazebo_ros_control.so">
				<robotNamespace>/</robotNamespace>
				<robotSimType>gazebo_ros_control/DefaultRobotHWSim</robotSimType>
				<legacyModeNS>true</legacyModeNS>
			</plugin>
		</gazebo>
		
		<!-- camera -->
	<gazebo reference="${robot_name}_link_ee">
	 <sensor type="camera" name="camera1">
		<update_rate>30.0</update_rate>
		<camera name="head">
		  <horizontal_fov>1.085595</horizontal_fov>
		  <image>
		    <width>1280</width>
		    <height>960</height>
		    <format>R8G8B8</format>
		  </image>
		  <clip>
		    <near>0.02</near>
		    <far>300</far>
		  </clip>
		  <noise>
		    <type>gaussian</type>
		    <!-- Noise is sampled independently per pixel on each frame.
		         That pixel's noise value is added to each of its color
		         channels, which at that point lie in the range [0,1]. -->
		    <mean>0.0</mean>
		    <stddev>0.007</stddev>
		  </noise>
		</camera>
		<plugin name="camera_controller" filename="libgazebo_ros_camera.so">
		  <alwaysOn>true</alwaysOn>
		  <updateRate>0.0</updateRate>
		  <cameraName>camera2</cameraName>
		  <imageTopicName>image_raw</imageTopicName>
		  <cameraInfoTopicName>camera_info</cameraInfoTopicName>
		  <frameName>kuka_iiwa_optical_link</frameName>
		  <hackBaseline>0.07</hackBaseline>
		  <distortionK1>0.0</distortionK1>
		  <distortionK2>0.0</distortionK2>
		  <distortionK3>0.0</distortionK3>
		  <distortionT1>0.0</distortionT1>
		  <distortionT2>0.0</distortionT2>
		</plugin>
	 </sensor>
	</gazebo>

    <gazebo reference="${robot_name}_link_0">
      <material>Gazebo/Black</material>
		</gazebo>
    <gazebo reference="${robot_name}_link_1">
      <material>Gazebo/Orange</material>
		</gazebo>
    <gazebo reference="${robot_name}_link_2">
      <material>Gazebo/Grey</material>
		</gazebo>
    <gazebo reference="${robot_name}_link_3">
      <material>Gazebo/Orange</material>
		</gazebo>
    <gazebo reference="${robot_name}_link_4">
      <material>Gazebo/Grey</material>
		</gazebo>
    <gazebo reference="${robot_name}_link_5">
      <material>Gazebo/Orange</material>
		</gazebo>
    <gazebo reference="${robot_name}_link_6">
      <material>Gazebo/Grey</material>
		</gazebo>
 

  </xacro:macro>
</robot>
